<?xml version="1.0" ?>
<!-- =================================================================================== -->
<!-- |    This document was autogenerated by xacro from /home/csrobot/hubo_ws/src/hubo_description/urdf/hubo_gripper.urdf.xacro | -->
<!-- |    EDITING THIS FILE BY HAND IS NOT RECOMMENDED                                 | -->
<!-- =================================================================================== -->
<robot name="DRC_HUBO">
  <link name="Body_TORSO">
    <inertial>
      <origin rpy="0 0 0" xyz="0.035284 1.0336E-06 -0.42399"/>
      <mass value="0.95687"/>
      <inertia ixx="0.06681" ixy="-3.173E-08" ixz="-0.0029038" iyy="0.034452" iyz="1.0171E-05" izz="0.03448"/>
    </inertial>
    <visual>
      <origin rpy="0 0 0" xyz="0 0 0"/>
      <geometry>
        <mesh filename="file://$(find hubo_description)/meshes/Body_TORSO.stl"/>
      </geometry>
      <material name="">
        <color rgba="0.79216 0.81961 0.93333 1"/>
      </material>
    </visual>
    <collision>
      <origin rpy="0 0 0" xyz="0 0 0"/>
      <geometry>
        <mesh filename="file://$(find hubo_description)/meshes/collision/Body_TORSO_col.stl"/>
      </geometry>
    </collision>
  </link>
  <link name="Body_LSP">
    <inertial>
      <origin rpy="0 0 0" xyz="0.035284 -0.242 -0.87989"/>
      <mass value="0.95687"/>
      <inertia ixx="0.06681" ixy="-3.173E-08" ixz="-0.0029038" iyy="0.034452" iyz="1.0171E-05" izz="0.03448"/>
    </inertial>
    <visual>
      <origin rpy="8.0188E-16 5.0144E-11 -1.2433E-15" xyz="0 0.242 0.4559"/>
      <geometry>
        <mesh filename="file://$(find hubo_description)/meshes/Body_LSP.stl"/>
      </geometry>
      <material name="">
        <color rgba="0.79216 0.81961 0.93333 1"/>
      </material>
    </visual>
    <collision>
      <origin rpy="0 0 0" xyz="0 0 0"/>
      <geometry>
        <mesh filename="file://$(find hubo_description)/meshes/collision/Body_LSP_col.stl"/>
      </geometry>
    </collision>
  </link>
  <joint name="LSP" type="revolute">
    <origin rpy="8.0188E-16 5.0144E-11 -1.2433E-15" xyz="0 0.242 0.4559"/>
    <parent link="Body_TORSO"/>
    <child link="Body_LSP"/>
    <axis xyz="0 1 0"/>
    <limit effort="0" lower="-1" upper="1" velocity="0"/>
  </joint>
  <link name="Body_LSR">
    <inertial>
      <origin rpy="0 0 0" xyz="0.035284 -0.242 -0.87989"/>
      <mass value="0.95687"/>
      <inertia ixx="0.06681" ixy="-3.173E-08" ixz="-0.0029038" iyy="0.034452" iyz="1.0171E-05" izz="0.03448"/>
    </inertial>
    <visual>
      <origin rpy="-1.3581E-15 -5.0143E-11 -1.7313E-12" xyz="0 0 0"/>
      <geometry>
        <mesh filename="file://$(find hubo_description)/meshes/Body_LSR.stl"/>
      </geometry>
      <material name="">
        <color rgba="0.79216 0.81961 0.93333 1"/>
      </material>
    </visual>
    <collision>
      <origin rpy="0 0 0" xyz="0 0 0"/>
      <geometry>
        <mesh filename="file://$(find hubo_description)/meshes/collision/Body_LSR_col.stl"/>
      </geometry>
    </collision>
  </link>
  <joint name="LSR" type="revolute">
    <origin rpy="-1.3581E-15 -5.0143E-11 -1.7313E-12" xyz="0 0 0"/>
    <parent link="Body_LSP"/>
    <child link="Body_LSR"/>
    <axis xyz="1 0 0"/>
    <limit effort="0" lower="-1" upper="1" velocity="0"/>
  </joint>
  <link name="Body_LSY">
    <inertial>
      <origin rpy="0 0 0" xyz="0.035284 -0.242 -0.87969"/>
      <mass value="0.95687"/>
      <inertia ixx="0.06681" ixy="-3.173E-08" ixz="-0.0029038" iyy="0.034452" iyz="1.0171E-05" izz="0.03448"/>
    </inertial>
    <visual>
      <origin rpy="1.2616E-15 -6.6613E-16 1.7322E-12" xyz="0 0 -0.0002"/>
      <geometry>
        <mesh filename="file://$(find hubo_description)/meshes/Body_LSY.stl"/>
      </geometry>
      <material name="">
        <color rgba="0.79216 0.81961 0.93333 1"/>
      </material>
    </visual>
    <collision>
      <origin rpy="0 0 0" xyz="0 0 0"/>
      <geometry>
        <mesh filename="file://$(find hubo_description)/meshes/collision/Body_LSY_col.stl"/>
      </geometry>
    </collision>
  </link>
  <joint name="LSY" type="revolute">
    <origin rpy="1.2616E-15 -6.6613E-16 1.7322E-12" xyz="0 0 -0.0002"/>
    <parent link="Body_LSR"/>
    <child link="Body_LSY"/>
    <axis xyz="0 0 -1"/>
    <limit effort="0" lower="-1" upper="1" velocity="0"/>
  </joint>
  <link name="Body_LEB">
    <inertial>
      <origin rpy="0 0 0" xyz="0.00028371 -0.24202 -0.52989"/>
      <mass value="0.95687"/>
      <inertia ixx="0.06681" ixy="-3.173E-08" ixz="-0.0029038" iyy="0.034452" iyz="1.0171E-05" izz="0.03448"/>
    </inertial>
    <visual>
      <origin rpy="-1.5045E-15 -1.8575E-14 -4.0905E-16" xyz="0.035001 2.0005E-05 -0.3498"/>
      <geometry>
        <mesh filename="file://$(find hubo_description)/meshes/Body_LEB.stl"/>
      </geometry>
      <material name="">
        <color rgba="0.79216 0.81961 0.93333 1"/>
      </material>
    </visual>
    <collision>
      <origin rpy="0 0 0" xyz="0 0 0"/>
      <geometry>
        <mesh filename="file://$(find hubo_description)/meshes/collision/Body_LEB_col.stl"/>
      </geometry>
    </collision>
  </link>
  <joint name="LEB" type="revolute">
    <origin rpy="-1.5045E-15 -1.8575E-14 -4.0905E-16" xyz="0.035001 2.0005E-05 -0.3498"/>
    <parent link="Body_LSY"/>
    <child link="Body_LEB"/>
    <axis xyz="0 -1 0"/>
    <limit effort="0" lower="-1" upper="1" velocity="0"/>
  </joint>
  <link name="Body_LWY">
    <inertial>
      <origin rpy="0 0 0" xyz="0.035284 -0.24202 -0.18989"/>
      <mass value="0.95687"/>
      <inertia ixx="0.06681" ixy="-3.173E-08" ixz="-0.0029038" iyy="0.034452" iyz="1.0171E-05" izz="0.03448"/>
    </inertial>
    <visual>
      <origin rpy="-2.8693E-16 3.6846E-15 4.6208E-16" xyz="-0.035 0 -0.34"/>
      <geometry>
        <mesh filename="file://$(find hubo_description)/meshes/Body_LWY.stl"/>
      </geometry>
      <material name="">
        <color rgba="0.79216 0.81961 0.93333 1"/>
      </material>
    </visual>
    <collision>
      <origin rpy="0 0 0" xyz="0 0 0"/>
      <geometry>
        <mesh filename="file://$(find hubo_description)/meshes/collision/Body_LWY_col.stl"/>
      </geometry>
    </collision>
  </link>
  <joint name="LWY" type="revolute">
    <origin rpy="-2.8693E-16 3.6846E-15 4.6208E-16" xyz="-0.035 0 -0.34"/>
    <parent link="Body_LEB"/>
    <child link="Body_LWY"/>
    <axis xyz="0 0 -1"/>
    <limit effort="0" lower="-1" upper="1" velocity="0"/>
  </joint>
  <link name="Body_LWP">
    <inertial>
      <origin rpy="0 0 0" xyz="0.035284 -0.24252 -0.18989"/>
      <mass value="0.95687"/>
      <inertia ixx="0.06681" ixy="-3.173E-08" ixz="-0.0029038" iyy="0.034452" iyz="1.0171E-05" izz="0.03448"/>
    </inertial>
    <visual>
      <origin rpy="1.4329E-15 -4.8572E-16 -6.1794E-15" xyz="0 0.0005 0"/>
      <geometry>
        <mesh filename="file://$(find hubo_description)/meshes/Body_LWP.stl"/>
      </geometry>
      <material name="">
        <color rgba="0.79216 0.81961 0.93333 1"/>
      </material>
    </visual>
    <collision>
      <origin rpy="0 0 0" xyz="0 0 0"/>
      <geometry>
        <mesh filename="file://$(find hubo_description)/meshes/collision/Body_LWP_col.stl"/>
      </geometry>
    </collision>
  </link>
  <joint name="LWP" type="revolute">
    <origin rpy="1.4329E-15 -4.8572E-16 -6.1794E-15" xyz="0 0.0005 0"/>
    <parent link="Body_LWY"/>
    <child link="Body_LWP"/>
    <axis xyz="0 -1 0"/>
    <limit effort="0" lower="-1" upper="1" velocity="0"/>
  </joint>
  <link name="Body_LWFT">
    <inertial>
      <origin rpy="0 0 0" xyz="-1.419E-15 0 -0.01"/>
      <mass value="0.072634"/>
      <inertia ixx="2.3412E-05" ixy="-1.8622E-21" ixz="-2.6466E-18" iyy="2.3412E-05" iyz="-1.7131E-21" izz="4.1982E-05"/>
    </inertial>
    <visual>
      <origin rpy="2.3828E-14 -1.4455E-13 1.9195E-15" xyz="0 0 -0.032"/>
      <geometry>
        <mesh filename="file://$(find hubo_description)/meshes/Body_LWFT.stl"/>
      </geometry>
      <material name="">
        <color rgba="0.79216 0.81961 0.93333 1"/>
      </material>
    </visual>
    <collision>
      <origin rpy="0 0 0" xyz="0 0 0"/>
      <geometry>
        <mesh filename="file://$(find hubo_description)/meshes/collision/Body_LWFT_col.stl"/>
      </geometry>
    </collision>
  </link>
  <joint name="LWFT" type="fixed">
    <origin rpy="2.3828E-14 -1.4455E-13 1.9195E-15" xyz="0 0 -0.032"/>
    <parent link="Body_LWP"/>
    <child link="Body_LWFT"/>
    <axis xyz="0 0 -1"/>
  </joint>
  <link name="Body_RSP">
    <inertial>
      <origin rpy="0 0 0" xyz="0.035284 0.242 -0.87989"/>
      <mass value="0.95687"/>
      <inertia ixx="0.06681" ixy="-3.173E-08" ixz="-0.0029038" iyy="0.034452" iyz="1.0171E-05" izz="0.03448"/>
    </inertial>
    <visual>
      <origin rpy="-3.2328E-16 -6.7696E-16 -6.2038E-18" xyz="0 -0.242 0.4559"/>
      <geometry>
        <mesh filename="file://$(find hubo_description)/meshes/Body_RSP.stl"/>
      </geometry>
      <material name="">
        <color rgba="0.79216 0.81961 0.93333 1"/>
      </material>
    </visual>
    <collision>
      <origin rpy="0 0 0" xyz="0 0 0"/>
      <geometry>
        <mesh filename="file://$(find hubo_description)/meshes/collision/Body_RSP_col.stl"/>
      </geometry>
    </collision>
  </link>
  <joint name="RSP" type="revolute">
    <origin rpy="-3.2328E-16 -6.7696E-16 -6.2038E-18" xyz="0 -0.242 0.4559"/>
    <parent link="Body_TORSO"/>
    <child link="Body_RSP"/>
    <axis xyz="0 -1 0"/>
    <limit effort="0" lower="-1" upper="1" velocity="0"/>
  </joint>
  <link name="Body_RSR">
    <inertial>
      <origin rpy="0 0 0" xyz="0.035284 0.242 -0.87989"/>
      <mass value="0.95687"/>
      <inertia ixx="0.06681" ixy="-3.173E-08" ixz="-0.0029038" iyy="0.034452" iyz="1.0171E-05" izz="0.03448"/>
    </inertial>
    <visual>
      <origin rpy="-4.8787E-17 1.6931E-15 -1.7325E-12" xyz="0 0 0"/>
      <geometry>
        <mesh filename="file://$(find hubo_description)/meshes/Body_RSR.stl"/>
      </geometry>
      <material name="">
        <color rgba="0.79216 0.81961 0.93333 1"/>
      </material>
    </visual>
    <collision>
      <origin rpy="0 0 0" xyz="0 0 0"/>
      <geometry>
        <mesh filename="file://$(find hubo_description)/meshes/collision/Body_RSR_col.stl"/>
      </geometry>
    </collision>
  </link>
  <joint name="RSR" type="revolute">
    <origin rpy="-4.8787E-17 1.6931E-15 -1.7325E-12" xyz="0 0 0"/>
    <parent link="Body_RSP"/>
    <child link="Body_RSR"/>
    <axis xyz="-1 0 0"/>
    <limit effort="0" lower="-1" upper="1" velocity="0"/>
  </joint>
  <link name="Body_RSY">
    <inertial>
      <origin rpy="0 0 0" xyz="0.035284 0.242 -0.87969"/>
      <mass value="0.95687"/>
      <inertia ixx="0.06681" ixy="-3.173E-08" ixz="-0.0029038" iyy="0.034452" iyz="1.0171E-05" izz="0.03448"/>
    </inertial>
    <visual>
      <origin rpy="-8.6847E-16 -2.1094E-15 1.733E-12" xyz="0 0 -0.0002"/>
      <geometry>
        <mesh filename="file://$(find hubo_description)/meshes/Body_RSY.stl"/>
      </geometry>
      <material name="">
        <color rgba="0.79216 0.81961 0.93333 1"/>
      </material>
    </visual>
    <collision>
      <origin rpy="0 0 0" xyz="0 0 0"/>
      <geometry>
        <mesh filename="file://$(find hubo_description)/meshes/collision/Body_RSY_col.stl"/>
      </geometry>
    </collision>
  </link>
  <joint name="RSY" type="revolute">
    <origin rpy="-8.6847E-16 -2.1094E-15 1.733E-12" xyz="0 0 -0.0002"/>
    <parent link="Body_RSR"/>
    <child link="Body_RSY"/>
    <axis xyz="0 0 1"/>
    <limit effort="0" lower="-1" upper="1" velocity="0"/>
  </joint>
  <link name="Body_REB">
    <inertial>
      <origin rpy="0 0 0" xyz="0.00028371 0.24202 -0.52989"/>
      <mass value="0.95687"/>
      <inertia ixx="0.06681" ixy="-3.173E-08" ixz="-0.0029038" iyy="0.034452" iyz="1.0171E-05" izz="0.03448"/>
    </inertial>
    <visual>
      <origin rpy="3.3743E-16 -1.6501E-14 8.9277E-17" xyz="0.035001 -2.0005E-05 -0.3498"/>
      <geometry>
        <mesh filename="file://$(find hubo_description)/meshes/Body_REB.stl"/>
      </geometry>
      <material name="">
        <color rgba="0.79216 0.81961 0.93333 1"/>
      </material>
    </visual>
    <collision>
      <origin rpy="0 0 0" xyz="0 0 0"/>
      <geometry>
        <mesh filename="file://$(find hubo_description)/meshes/collision/Body_REB_col.stl"/>
      </geometry>
    </collision>
  </link>
  <joint name="REB" type="revolute">
    <origin rpy="3.3743E-16 -1.6501E-14 8.9277E-17" xyz="0.035001 -2.0005E-05 -0.3498"/>
    <parent link="Body_RSY"/>
    <child link="Body_REB"/>
    <axis xyz="0 -1 0"/>
    <limit effort="0" lower="-1" upper="1" velocity="0"/>
  </joint>
  <link name="Body_RWY">
    <inertial>
      <origin rpy="0 0 0" xyz="0.035284 0.24202 -0.18989"/>
      <mass value="0.95687"/>
      <inertia ixx="0.06681" ixy="-3.173E-08" ixz="-0.0029038" iyy="0.034452" iyz="1.0171E-05" izz="0.03448"/>
    </inertial>
    <visual>
      <origin rpy="1.9101E-16 -8.4655E-16 1.4719E-15" xyz="-0.035 0 -0.34"/>
      <geometry>
        <mesh filename="file://$(find hubo_description)/meshes/Body_RWY.stl"/>
      </geometry>
      <material name="">
        <color rgba="0.79216 0.81961 0.93333 1"/>
      </material>
    </visual>
    <collision>
      <origin rpy="0 0 0" xyz="0 0 0"/>
      <geometry>
        <mesh filename="file://$(find hubo_description)/meshes/collision/Body_RWY_col.stl"/>
      </geometry>
    </collision>
  </link>
  <joint name="RWY" type="revolute">
    <origin rpy="1.9101E-16 -8.4655E-16 1.4719E-15" xyz="-0.035 0 -0.34"/>
    <parent link="Body_REB"/>
    <child link="Body_RWY"/>
    <axis xyz="0 0 1"/>
    <limit effort="0" lower="-1" upper="1" velocity="0"/>
  </joint>
  <link name="Body_RWP">
    <inertial>
      <origin rpy="0 0 0" xyz="0.035284 0.24252 -0.18989"/>
      <mass value="0.95687"/>
      <inertia ixx="0.06681" ixy="-3.173E-08" ixz="-0.0029038" iyy="0.034452" iyz="1.0171E-05" izz="0.03448"/>
    </inertial>
    <visual>
      <origin rpy="6.9562E-16 8.3267E-16 -1.1633E-15" xyz="0 -0.0005 0"/>
      <geometry>
        <mesh filename="file://$(find hubo_description)/meshes/Body_RWP.stl"/>
      </geometry>
      <material name="">
        <color rgba="0.79216 0.81961 0.93333 1"/>
      </material>
    </visual>
    <collision>
      <origin rpy="0 0 0" xyz="0 0 0"/>
      <geometry>
        <mesh filename="file://$(find hubo_description)/meshes/collision/Body_RWP_col.stl"/>
      </geometry>
    </collision>
  </link>
  <joint name="RWP" type="revolute">
    <origin rpy="6.9562E-16 8.3267E-16 -1.1633E-15" xyz="0 -0.0005 0"/>
    <parent link="Body_RWY"/>
    <child link="Body_RWP"/>
    <axis xyz="0 -1 0"/>
    <limit effort="0" lower="-1" upper="1" velocity="0"/>
  </joint>
  <link name="Body_RWFT">
    <inertial>
      <origin rpy="0 0 0" xyz="1.2757E-14 -1.1297E-14 -0.01"/>
      <mass value="0.072634"/>
      <inertia ixx="2.3412E-05" ixy="8.8441E-21" ixz="-2.465E-20" iyy="2.3412E-05" iyz="5.7918E-21" izz="4.1982E-05"/>
    </inertial>
    <visual>
      <origin rpy="-2.6296E-14 -1.2546E-14 -1.1419E-15" xyz="0 0 -0.03255"/>
      <geometry>
        <mesh filename="file://$(find hubo_description)/meshes/Body_RWFT.stl"/>
      </geometry>
      <material name="">
        <color rgba="0.79216 0.81961 0.93333 1"/>
      </material>
    </visual>
    <collision>
      <origin rpy="0 0 0" xyz="0 0 0"/>
      <geometry>
        <mesh filename="file://$(find hubo_description)/meshes/collision/Body_RWFT_col.stl"/>
      </geometry>
    </collision>
  </link>
  <joint name="RWFT" type="fixed">
    <origin rpy="-2.6296E-14 -1.2546E-14 -1.1419E-15" xyz="0 0 -0.03255"/>
    <parent link="Body_RWP"/>
    <child link="Body_RWFT"/>
    <axis xyz="0 0 1"/>
  </joint>
  <link name="Body_WST">
    <inertial>
      <origin rpy="0 0 0" xyz="1.2178E-15 -3.4001E-16 0.1477"/>
      <mass value="0.073485"/>
      <inertia ixx="0.00062375" ixy="-1.2817E-19" ixz="-2.1576E-18" iyy="0.00013385" iyz="1.8741E-18" izz="0.00055098"/>
    </inertial>
    <visual>
      <origin rpy="-2.3486E-15 1.377E-15 8.1825E-15" xyz="0 0 0"/>
      <geometry>
        <mesh filename="file://$(find hubo_description)/meshes/Body_WST.stl"/>
      </geometry>
      <material name="">
        <color rgba="0.79216 0.81961 0.93333 1"/>
      </material>
    </visual>
    <collision>
      <origin rpy="0 0 0" xyz="0 0 0"/>
      <geometry>
        <mesh filename="file://$(find hubo_description)/meshes/collision/Body_WST_col.stl"/>
      </geometry>
    </collision>
  </link>
  <joint name="WST" type="revolute">
    <origin rpy="-2.3486E-15 1.377E-15 8.1825E-15" xyz="0 0 0"/>
    <parent link="Body_TORSO"/>
    <child link="Body_WST"/>
    <axis xyz="0 0 1"/>
    <limit effort="0" lower="-1" upper="1" velocity="0"/>
  </joint>
  <link name="Body_LHY">
    <inertial>
      <origin rpy="0 0 0" xyz="0.035284 -0.099999 -0.42399"/>
      <mass value="0.95687"/>
      <inertia ixx="0.06681" ixy="-3.173E-08" ixz="-0.0029038" iyy="0.034452" iyz="1.0171E-05" izz="0.03448"/>
    </inertial>
    <visual>
      <origin rpy="2.3486E-15 -2.4735E-16 -9.5626E-15" xyz="0 0.1 0"/>
      <geometry>
        <mesh filename="file://$(find hubo_description)/meshes/Body_LHY.stl"/>
      </geometry>
      <material name="">
        <color rgba="0.79216 0.81961 0.93333 1"/>
      </material>
    </visual>
    <collision>
      <origin rpy="0 0 0" xyz="0 0 0"/>
      <geometry>
        <mesh filename="file://$(find hubo_description)/meshes/collision/Body_LHY_col.stl"/>
      </geometry>
    </collision>
  </link>
  <joint name="LHY" type="revolute">
    <origin rpy="2.3486E-15 -2.4735E-16 -9.5626E-15" xyz="0 0.1 0"/>
    <parent link="Body_WST"/>
    <child link="Body_LHY"/>
    <axis xyz="0 0 1"/>
    <limit effort="0" lower="-1" upper="1" velocity="0"/>
  </joint>
  <link name="Body_LHR">
    <inertial>
      <origin rpy="0 0 0" xyz="0.035284 -0.099999 -0.42399"/>
      <mass value="0.95687"/>
      <inertia ixx="0.06681" ixy="-3.173E-08" ixz="-0.0029038" iyy="0.034452" iyz="1.0171E-05" izz="0.03448"/>
    </inertial>
    <visual>
      <origin rpy="2.2525E-16 1.9845E-16 7.1786E-17" xyz="0 0 0"/>
      <geometry>
        <mesh filename="file://$(find hubo_description)/meshes/Body_LHR.stl"/>
      </geometry>
      <material name="">
        <color rgba="0.79216 0.81961 0.93333 1"/>
      </material>
    </visual>
    <collision>
      <origin rpy="0 0 0" xyz="0 0 0"/>
      <geometry>
        <mesh filename="file://$(find hubo_description)/meshes/collision/Body_LHR_col.stl"/>
      </geometry>
    </collision>
  </link>
  <joint name="LHR" type="revolute">
    <origin rpy="2.2525E-16 1.9845E-16 7.1786E-17" xyz="0 0 0"/>
    <parent link="Body_LHY"/>
    <child link="Body_LHR"/>
    <axis xyz="-1 0 0"/>
    <limit effort="0" lower="-1" upper="1" velocity="0"/>
  </joint>
  <link name="Body_LHP">
    <inertial>
      <origin rpy="0 0 0" xyz="0.0020999 -0.066041 -0.21148"/>
      <mass value="7.718E-05"/>
      <inertia ixx="2.3141E-07" ixy="6.5972E-12" ixz="-3.0859E-10" iyy="2.3156E-07" iyz="-6.644E-10" izz="1.6468E-10"/>
    </inertial>
    <visual>
      <origin rpy="1.2158E-15 -1.1763E-16 -2.7528E-16" xyz="0 0 0"/>
      <geometry>
        <mesh filename="file://$(find hubo_description)/meshes/Body_LHP.stl"/>
      </geometry>
      <material name="">
        <color rgba="0.79216 0.81961 0.93333 1"/>
      </material>
    </visual>
    <collision>
      <origin rpy="0 0 0" xyz="0 0 0"/>
      <geometry>
        <mesh filename="file://$(find hubo_description)/meshes/collision/Body_LHP_col.stl"/>
      </geometry>
    </collision>
  </link>
  <joint name="LHP" type="revolute">
    <origin rpy="1.2158E-15 -1.1763E-16 -2.7528E-16" xyz="0 0 0"/>
    <parent link="Body_LHR"/>
    <child link="Body_LHP"/>
    <axis xyz="0 1 0"/>
    <limit effort="0" lower="-1" upper="1" velocity="0"/>
  </joint>
  <link name="Body_LKN">
    <inertial>
      <origin rpy="0 0 0" xyz="-0.0233 -0.14148 0.7319"/>
      <mass value="0"/>
      <inertia ixx="0" ixy="0" ixz="0" iyy="0" iyz="0" izz="0"/>
    </inertial>
    <visual>
      <origin rpy="1.1306E-15 8.3267E-16 -3.1457E-15" xyz="0 0 -0.38"/>
      <geometry>
        <mesh filename="file://$(find hubo_description)/meshes/Body_LKN.stl"/>
      </geometry>
      <material name="">
        <color rgba="0.79216 0.81961 0.93333 1"/>
      </material>
    </visual>
    <collision>
      <origin rpy="0 0 0" xyz="0 0 0"/>
      <geometry>
        <mesh filename="file://$(find hubo_description)/meshes/collision/Body_LKN_col.stl"/>
      </geometry>
    </collision>
  </link>
  <joint name="LKN" type="revolute">
    <origin rpy="1.1306E-15 8.3267E-16 -3.1457E-15" xyz="0 0 -0.38"/>
    <parent link="Body_LHP"/>
    <child link="Body_LKN"/>
    <axis xyz="0 -1 0"/>
    <limit effort="0" lower="-1" upper="1" velocity="0"/>
  </joint>
  <link name="Body_LWH">
    <inertial>
      <origin rpy="0 0 0" xyz="-0.010467 -0.17918 0.086008"/>
      <mass value="0.95687"/>
      <inertia ixx="0.06681" ixy="-3.173E-08" ixz="-0.0029038" iyy="0.034452" iyz="1.0171E-05" izz="0.03448"/>
    </inertial>
    <visual>
      <origin rpy="2.7507E-16 -8.8818E-16 8.5835E-17" xyz="0.045751 0 -0.13"/>
      <geometry>
        <mesh filename="file://$(find hubo_description)/meshes/Body_LWH.stl"/>
      </geometry>
      <material name="">
        <color rgba="0.79216 0.81961 0.93333 1"/>
      </material>
    </visual>
    <collision>
      <origin rpy="0 0 0" xyz="0 0 0"/>
      <geometry>
        <mesh filename="file://$(find hubo_description)/meshes/collision/Body_LWH_col.stl"/>
      </geometry>
    </collision>
  </link>
  <joint name="LWH" type="continuous">
    <origin rpy="2.7507E-16 -8.8818E-16 8.5835E-17" xyz="0.045751 0 -0.13"/>
    <parent link="Body_LKN"/>
    <child link="Body_LWH"/>
    <axis xyz="0 1 0"/>
  </joint>
  <link name="Body_LAP">
    <inertial>
      <origin rpy="0 0 0" xyz="0.035284 -0.099999 0.31601"/>
      <mass value="0.95687"/>
      <inertia ixx="0.06681" ixy="-3.173E-08" ixz="-0.0029038" iyy="0.034452" iyz="1.0171E-05" izz="0.03448"/>
    </inertial>
    <visual>
      <origin rpy="-2.2941E-15 -6.6613E-16 5.5206E-15" xyz="0 0 -0.36"/>
      <geometry>
        <mesh filename="file://$(find hubo_description)/meshes/Body_LAP.stl"/>
      </geometry>
      <material name="">
        <color rgba="0.79216 0.81961 0.93333 1"/>
      </material>
    </visual>
    <collision>
      <origin rpy="0 0 0" xyz="0 0 0"/>
      <geometry>
        <mesh filename="file://$(find hubo_description)/meshes/collision/Body_LAP_col.stl"/>
      </geometry>
    </collision>
  </link>
  <joint name="LAP" type="revolute">
    <origin rpy="-2.2941E-15 -6.6613E-16 5.5206E-15" xyz="0 0 -0.36"/>
    <parent link="Body_LKN"/>
    <child link="Body_LAP"/>
    <axis xyz="0 -1 0"/>
    <limit effort="0" lower="-1" upper="1" velocity="0"/>
  </joint>
  <link name="Body_LAR">
    <inertial>
      <origin rpy="0 0 0" xyz="0.035284 -0.099999 0.34101"/>
      <mass value="0.95687"/>
      <inertia ixx="0.06681" ixy="-3.1786E-08" ixz="-0.0029038" iyy="0.034452" iyz="1.0171E-05" izz="0.03448"/>
    </inertial>
    <visual>
      <origin rpy="5.8299E-13 -1.4879E-15 -2.6184E-15" xyz="0 0 -0.025"/>
      <geometry>
        <mesh filename="file://$(find hubo_description)/meshes/Body_LAR.stl"/>
      </geometry>
      <material name="">
        <color rgba="0.79216 0.81961 0.93333 1"/>
      </material>
    </visual>
    <collision>
      <origin rpy="0 0 0" xyz="0 0 0"/>
      <geometry>
        <mesh filename="file://$(find hubo_description)/meshes/collision/Body_LAR_col.stl"/>
      </geometry>
    </collision>
  </link>
  <joint name="LAR" type="revolute">
    <origin rpy="5.8299E-13 -1.4879E-15 -2.6184E-15" xyz="0 0 -0.025"/>
    <parent link="Body_LAP"/>
    <child link="Body_LAR"/>
    <axis xyz="1 0 0"/>
    <limit effort="0" lower="-1" upper="1" velocity="0"/>
  </joint>
  <link name="Body_LAFT">
    <inertial>
      <origin rpy="0 0 0" xyz="0.035284 -0.099999 0.39601"/>
      <mass value="0.95687"/>
      <inertia ixx="0.06681" ixy="-3.1786E-08" ixz="-0.0029038" iyy="0.034452" iyz="1.0171E-05" izz="0.03448"/>
    </inertial>
    <visual>
      <origin rpy="5.8333E-13 1.2546E-14 -2.936E-15" xyz="0 0 -0.055"/>
      <geometry>
        <mesh filename="file://$(find hubo_description)/meshes/Body_LAFT.stl"/>
      </geometry>
      <material name="">
        <color rgba="0.79216 0.81961 0.93333 1"/>
      </material>
    </visual>
    <collision>
      <origin rpy="0 0 0" xyz="0 0 0"/>
      <geometry>
        <mesh filename="file://$(find hubo_description)/meshes/collision/Body_LAFT_col.stl"/>
      </geometry>
    </collision>
  </link>
  <joint name="LAFT" type="fixed">
    <origin rpy="5.8333E-13 1.2546E-14 -2.936E-15" xyz="0 0 -0.055"/>
    <parent link="Body_LAR"/>
    <child link="Body_LAFT"/>
    <axis xyz="0 0 1"/>
  </joint>
  <link name="Body_RHY">
    <inertial>
      <origin rpy="0 0 0" xyz="0.035284 0.1 -0.42399"/>
      <mass value="0.95687"/>
      <inertia ixx="0.06681" ixy="-3.1786E-08" ixz="-0.0029038" iyy="0.034452" iyz="1.0171E-05" izz="0.03448"/>
    </inertial>
    <visual>
      <origin rpy="2.397E-15 4.6327E-16 -8.1718E-15" xyz="0 -0.1 0"/>
      <geometry>
        <mesh filename="file://$(find hubo_description)/meshes/Body_RHY.stl"/>
      </geometry>
      <material name="">
        <color rgba="0.79216 0.81961 0.93333 1"/>
      </material>
    </visual>
    <collision>
      <origin rpy="0 0 0" xyz="0 0 0"/>
      <geometry>
        <mesh filename="file://$(find hubo_description)/meshes/collision/Body_RHY_col.stl"/>
      </geometry>
    </collision>
  </link>
  <joint name="RHY" type="revolute">
    <origin rpy="2.397E-15 4.6327E-16 -8.1718E-15" xyz="0 -0.1 0"/>
    <parent link="Body_WST"/>
    <child link="Body_RHY"/>
    <axis xyz="0 0 -1"/>
    <limit effort="0" lower="-1" upper="1" velocity="0"/>
  </joint>
  <link name="Body_RHR">
    <inertial>
      <origin rpy="0 0 0" xyz="-0.035284 -0.1 -0.42399"/>
      <mass value="0.95687"/>
      <inertia ixx="0.06681" ixy="-3.1786E-08" ixz="0.0029038" iyy="0.034452" iyz="-1.0171E-05" izz="0.03448"/>
    </inertial>
    <visual>
      <origin rpy="4.3197E-16 3.4822E-17 3.1416" xyz="0 0 0"/>
      <geometry>
        <mesh filename="file://$(find hubo_description)/meshes/Body_RHR.stl"/>
      </geometry>
      <material name="">
        <color rgba="0.79216 0.81961 0.93333 1"/>
      </material>
    </visual>
    <collision>
      <origin rpy="0 0 0" xyz="0 0 0"/>
      <geometry>
        <mesh filename="file://$(find hubo_description)/meshes/collision/Body_RHR_col.stl"/>
      </geometry>
    </collision>
  </link>
  <joint name="RHR" type="revolute">
    <origin rpy="4.3197E-16 3.4822E-17 3.1416" xyz="0 0 0"/>
    <parent link="Body_RHY"/>
    <child link="Body_RHR"/>
    <axis xyz="-1 0 0"/>
    <limit effort="0" lower="-1" upper="1" velocity="0"/>
  </joint>
  <link name="Body_RHP">
    <inertial>
      <origin rpy="0 0 0" xyz="0.00094043 0.066113 -0.22429"/>
      <mass value="2.7871E-05"/>
      <inertia ixx="2.3651E-07" ixy="-2.9545E-12" ixz="-2.6163E-10" iyy="2.3653E-07" iyz="7.0464E-10" izz="2.4463E-11"/>
    </inertial>
    <visual>
      <origin rpy="6.1145E-16 -7.3376E-16 -3.1416" xyz="0 0 0"/>
      <geometry>
        <mesh filename="file://$(find hubo_description)/meshes/Body_RHP.stl"/>
      </geometry>
      <material name="">
        <color rgba="0.79216 0.81961 0.93333 1"/>
      </material>
    </visual>
    <collision>
      <origin rpy="0 0 0" xyz="0 0 0"/>
      <geometry>
        <mesh filename="file://$(find hubo_description)/meshes/collision/Body_RHP_col.stl"/>
      </geometry>
    </collision>
  </link>
  <joint name="RHP" type="revolute">
    <origin rpy="6.1145E-16 -7.3376E-16 -3.1416" xyz="0 0 0"/>
    <parent link="Body_RHR"/>
    <child link="Body_RHP"/>
    <axis xyz="0 -1 0"/>
    <limit effort="0" lower="-1" upper="1" velocity="0"/>
  </joint>
  <link name="Body_RKN">
    <inertial>
      <origin rpy="0 0 0" xyz="-0.0233 0.058524 0.7319"/>
      <mass value="0"/>
      <inertia ixx="0" ixy="0" ixz="0" iyy="0" iyz="0" izz="0"/>
    </inertial>
    <visual>
      <origin rpy="-2.0986E-16 8.1776E-12 1.5979E-15" xyz="0 0 -0.38"/>
      <geometry>
        <mesh filename="file://$(find hubo_description)/meshes/Body_RKN.stl"/>
      </geometry>
      <material name="">
        <color rgba="0.79216 0.81961 0.93333 1"/>
      </material>
    </visual>
    <collision>
      <origin rpy="0 0 0" xyz="0 0 0"/>
      <geometry>
        <mesh filename="file://$(find hubo_description)/meshes/collision/Body_RKN_col.stl"/>
      </geometry>
    </collision>
  </link>
  <joint name="RKN" type="revolute">
    <origin rpy="-2.0986E-16 8.1776E-12 1.5979E-15" xyz="0 0 -0.38"/>
    <parent link="Body_RHP"/>
    <child link="Body_RKN"/>
    <axis xyz="0 -1 0"/>
    <limit effort="0" lower="-1" upper="1" velocity="0"/>
  </joint>
  <link name="Body_RWH">
    <inertial>
      <origin rpy="0 0 0" xyz="-0.010467 0.18129 0.086008"/>
      <mass value="0.95687"/>
      <inertia ixx="0.06681" ixy="-3.1786E-08" ixz="-0.0029038" iyy="0.034452" iyz="1.0171E-05" izz="0.03448"/>
    </inertial>
    <visual>
      <origin rpy="2.8536E-16 -8.1837E-12 -1.0744E-16" xyz="0.045751 0 -0.13"/>
      <geometry>
        <mesh filename="file://$(find hubo_description)/meshes/Body_RWH.stl"/>
      </geometry>
      <material name="">
        <color rgba="0.79216 0.81961 0.93333 1"/>
      </material>
    </visual>
    <collision>
      <origin rpy="0 0 0" xyz="0 0 0"/>
      <geometry>
        <mesh filename="file://$(find hubo_description)/meshes/collision/Body_RWH_col.stl"/>
      </geometry>
    </collision>
  </link>
  <joint name="RWH" type="revolute">
    <origin rpy="2.8536E-16 -8.1837E-12 -1.0744E-16" xyz="0.045751 0 -0.13"/>
    <parent link="Body_RKN"/>
    <child link="Body_RWH"/>
    <axis xyz="0 -1 0"/>
    <limit effort="0" lower="-1" upper="1" velocity="0"/>
  </joint>
  <link name="Body_RAP">
    <inertial>
      <origin rpy="0 0 0" xyz="0.035284 0.1 0.31601"/>
      <mass value="0.95687"/>
      <inertia ixx="0.06681" ixy="-3.1786E-08" ixz="-0.0029038" iyy="0.034452" iyz="1.0171E-05" izz="0.03448"/>
    </inertial>
    <visual>
      <origin rpy="-2.9557E-16 -8.1773E-12 -3.8327E-15" xyz="0 0 -0.36"/>
      <geometry>
        <mesh filename="file://$(find hubo_description)/meshes/Body_RAP.stl"/>
      </geometry>
      <material name="">
        <color rgba="0.79216 0.81961 0.93333 1"/>
      </material>
    </visual>
    <collision>
      <origin rpy="0 0 0" xyz="0 0 0"/>
      <geometry>
        <mesh filename="file://$(find hubo_description)/meshes/collision/Body_RAP_col.stl"/>
      </geometry>
    </collision>
  </link>
  <joint name="RAP" type="revolute">
    <origin rpy="-2.9557E-16 -8.1773E-12 -3.8327E-15" xyz="0 0 -0.36"/>
    <parent link="Body_RKN"/>
    <child link="Body_RAP"/>
    <axis xyz="0 -1 0"/>
    <limit effort="0" lower="-1" upper="1" velocity="0"/>
  </joint>
  <link name="Body_RAR">
    <inertial>
      <origin rpy="0 0 0" xyz="0.035284 0.1 0.34101"/>
      <mass value="0.95687"/>
      <inertia ixx="0.06681" ixy="-3.1786E-08" ixz="-0.0029038" iyy="0.034452" iyz="1.0171E-05" izz="0.03448"/>
    </inertial>
    <visual>
      <origin rpy="-8.9084E-16 -4.0165E-15 1.106E-15" xyz="0 0 -0.025"/>
      <geometry>
        <mesh filename="file://$(find hubo_description)/meshes/Body_RAR.stl"/>
      </geometry>
      <material name="">
        <color rgba="0.79216 0.81961 0.93333 1"/>
      </material>
    </visual>
    <collision>
      <origin rpy="0 0 0" xyz="0 0 0"/>
      <geometry>
        <mesh filename="file://$(find hubo_description)/meshes/collision/Body_RAR_col.stl"/>
      </geometry>
    </collision>
  </link>
  <joint name="RAR" type="revolute">
    <origin rpy="-8.9084E-16 -4.0165E-15 1.106E-15" xyz="0 0 -0.025"/>
    <parent link="Body_RAP"/>
    <child link="Body_RAR"/>
    <axis xyz="1 0 0"/>
    <limit effort="0" lower="-1" upper="1" velocity="0"/>
  </joint>
  <link name="Body_RAFT">
    <inertial>
      <origin rpy="0 0 0" xyz="0.035284 0.1 0.39601"/>
      <mass value="0.95687"/>
      <inertia ixx="0.06681" ixy="-3.1786E-08" ixz="-0.0029038" iyy="0.034452" iyz="1.0171E-05" izz="0.03448"/>
    </inertial>
    <visual>
      <origin rpy="1.1618E-12 1.796E-15 2.7197E-16" xyz="0 0 -0.055"/>
      <geometry>
        <mesh filename="file://$(find hubo_description)/meshes/Body_RAFT.stl"/>
      </geometry>
      <material name="">
        <color rgba="0.79216 0.81961 0.93333 1"/>
      </material>
    </visual>
    <collision>
      <origin rpy="0 0 0" xyz="0 0 0"/>
      <geometry>
        <mesh filename="file://$(find hubo_description)/meshes/collision/Body_RAFT_col.stl"/>
      </geometry>
    </collision>
  </link>
  <joint name="RAFT" type="fixed">
    <origin rpy="1.1618E-12 1.796E-15 2.7197E-16" xyz="0 0 -0.055"/>
    <parent link="Body_RAR"/>
    <child link="Body_RAFT"/>
    <axis xyz="0 0 -1"/>
  </joint>
  <link name="Body_RF2_a1">
    <!--Finger 1 link 1-->
    <visual>
      <origin rpy="0 0.740298856 -7.850700415" xyz="0.026857 -0.016806 -0.131594"/>
      <geometry>
        <mesh filename="file://$(find hubo_description)/hubo_gripper_meshes/Body_RF2_a1.STL"/>
      </geometry>
      <material name="">
        <color rgba="0.79216 0.81961 0.93333 1"/>
      </material>
    </visual>
    <collision>
      <origin rpy="0 0.740298856 -7.850700415" xyz="0.026857 -0.016806 -0.131594"/>
      <geometry>
        <mesh filename="file://$(find hubo_description)/hubo_gripper_meshes/Body_RF2_a1_col.STL"/>
      </geometry>
    </collision>
    <inertial>
      <origin rpy="0 0 0" xyz="0 0 0"/>
      <mass value="0.038683"/>
      <inertia ixx="1.143e-04" ixy="7e-06" ixz="-6.53e-05" iyy="2.17e-04" iyz="-1e-05" izz="1.314e-04"/>
    </inertial>
  </link>
  <link name="Body_RF2_a2">
    <!--Finger 1 link 2-->
    <visual>
      <origin rpy="0 1.44624963 -1.506016686" xyz="0.025625 -0.018272 -0.187882"/>
      <geometry>
        <mesh filename="file://$(find hubo_description)/hubo_gripper_meshes/Body_RF2_a2.STL"/>
      </geometry>
      <material name="">
        <color rgba="0.79216 0.81961 0.93333 1"/>
      </material>
    </visual>
    <collision>
      <origin rpy="0 1.44624963 -1.506016686" xyz="0.025625 -0.018272 -0.187882"/>
      <geometry>
        <mesh filename="file://$(find hubo_description)/hubo_gripper_meshes/Body_RF2_a2_col.STL"/>
      </geometry>
    </collision>
    <inertial>
      <origin rpy="0 0 0" xyz="0 0 0"/>
      <mass value="0.021949"/>
      <inertia ixx="2.31e-05" ixy="9e-06" ixz="-4.6e-06" iyy="7.09e-05" iyz="-5e-06" izz="6.69e-05"/>
    </inertial>
  </link>
  <link name="Body_RF2_a3">
    <!--Finger 1 link 3-->
    <visual>
      <origin rpy="0 1.796537212 -1.524014522" xyz="0.026302 -0.023312 -0.222796"/>
      <geometry>
        <mesh filename="file://$(find hubo_description)/hubo_gripper_meshes/Body_RF2_a3.STL"/>
      </geometry>
      <material name="">
        <color rgba="0.79216 0.81961 0.93333 1"/>
      </material>
    </visual>
    <collision>
      <origin rpy="0 1.796537212 -1.524014522" xyz="0.026302 -0.023312 -0.222796"/>
      <geometry>
        <mesh filename="file://$(find hubo_description)/hubo_gripper_meshes/Body_RF2_a3_col.STL"/>
      </geometry>
    </collision>
    <inertial>
      <origin rpy="0 0 0" xyz="0 0 0"/>
      <mass value="0.0115"/>
      <inertia ixx="7.2e-05" ixy="1e-06" ixz="2.9e-05" iyy="1.67e-05" iyz="1e-06" izz="1.84e-05"/>
    </inertial>
  </link>
  <joint name="RHAND_a1" type="revolute">
    <!--Joints connecting the links together and to the hand-->
    <parent link="Body_RF1"/>
    <child link="Body_RF2_a1"/>
    <axis xyz="1 0 0"/>
    <limit effort="100" lower="0" upper="1" velocity="100"/>
  </joint>
  <joint name="RHAND_a2" type="revolute">
    <parent link="Body_RF2_a1"/>
    <child link="Body_RF2_a2"/>
    <axis xyz="1 0 0"/>
    <limit effort="100" lower="0" upper="1" velocity="100"/>
  </joint>
  <joint name="RHAND_a3" type="revolute">
    <parent link="Body_RF2_a2"/>
    <child link="Body_RF2_a3"/>
    <axis xyz="1 0 0"/>
    <limit effort="100" lower="0" upper="1" velocity="100"/>
  </joint>
  <link name="Body_RF2_b1">
    <!--Finger 2 link 1-->
    <visual>
      <origin rpy="-0.02640700612 0.7209169742 -1.458412831" xyz="-0.026104 -0.018335 -0.131748"/>
      <geometry>
        <mesh filename="file://$(find hubo_description)/hubo_gripper_meshes/Body_RF2_b1.STL"/>
      </geometry>
      <material name="">
        <color rgba="0.79216 0.81961 0.93333 1"/>
      </material>
    </visual>
    <collision>
      <origin rpy="-0.02640700612 0.7209169742 -1.458412831" xyz="-0.026104 -0.018335 -0.131748"/>
      <geometry>
        <mesh filename="file://$(find hubo_description)/hubo_gripper_meshes/Body_RF2_b1_col.STL"/>
      </geometry>
    </collision>
    <inertial>
      <origin rpy="0 0 0" xyz="0 0 0"/>
      <mass value="0.038683"/>
      <inertia ixx="1.143e-04" ixy="7e-06" ixz="-6.53e-05" iyy="2.17e-04" iyz="-1e-05" izz="1.314e-04"/>
    </inertial>
  </link>
  <link name="Body_RF2_b2">
    <!--Finger 2 link 2-->
    <visual>
      <origin rpy="0 1.519176469 -1.523696872" xyz="-0.02517 -0.021352 -0.186164"/>
      <geometry>
        <mesh filename="file://$(find hubo_description)/hubo_gripper_meshes/Body_RF2_b2.STL"/>
      </geometry>
      <material name="">
        <color rgba="0.79216 0.81961 0.93333 1"/>
      </material>
    </visual>
    <collision>
      <origin rpy="0 1.519176469 -1.523696872" xyz="-0.02517 -0.021352 -0.186164"/>
      <geometry>
        <mesh filename="file://$(find hubo_description)/hubo_gripper_meshes/Body_RF2_b2_col.STL"/>
      </geometry>
    </collision>
    <inertial>
      <origin rpy="0 0 0" xyz="0 0 0"/>
      <mass value="0.021949"/>
      <inertia ixx="2.31e-05" ixy="9e-06" ixz="-4.6e-06" iyy="7.09e-05" iyz="-5e-06" izz="6.69e-05"/>
    </inertial>
  </link>
  <link name="Body_RF2_b3">
    <!--Finger 2 link 3-->
    <visual>
      <origin rpy="-3.155066595 1.304865745 -4.616134072" xyz="-0.025512 -0.023901 -0.221898"/>
      <geometry>
        <mesh filename="file://$(find hubo_description)/hubo_gripper_meshes/Body_RF2_b3.STL"/>
      </geometry>
      <material name="">
        <color rgba="0.79216 0.81961 0.93333 1"/>
      </material>
    </visual>
    <collision>
      <origin rpy="-3.155066595 1.304865745 -4.616134072" xyz="-0.025512 -0.023901 -0.221898"/>
      <geometry>
        <mesh filename="file://$(find hubo_description)/hubo_gripper_meshes/Body_RF2_b3_col.STL"/>
      </geometry>
    </collision>
    <inertial>
      <origin rpy="0 0 0" xyz="0 0 0"/>
      <mass value="0.0115"/>
      <inertia ixx="7.2e-05" ixy="1e-06" ixz="2.9e-05" iyy="1.67e-05" iyz="1e-06" izz="1.84e-05"/>
    </inertial>
  </link>
  <joint name="RHAND_b1" type="revolute">
    <!--Joints connecting the links together and to the hand-->
    <parent link="Body_RF1"/>
    <child link="Body_RF2_b1"/>
    <axis xyz="1 0 0"/>
    <limit effort="10000000" lower="0" upper="1" velocity="100"/>
  </joint>
  <joint name="RHAND_b2" type="revolute">
    <parent link="Body_RF2_b1"/>
    <child link="Body_RF2_b2"/>
    <axis xyz="1 0 0"/>
    <limit effort="10000000" lower="0" upper="1" velocity="100"/>
  </joint>
  <joint name="RHAND_b3" type="revolute">
    <parent link="Body_RF2_b2"/>
    <child link="Body_RF2_b3"/>
    <axis xyz="1 0 0"/>
    <limit effort="10000000" lower="0" upper="1" velocity="100"/>
  </joint>
  <link name="Body_RF2_c1">
    <!--Finger 3 link 1-->
    <visual>
      <origin rpy="-0.0022611089525 -0.7586841539 -1.53395243" xyz="-0.000564 0.015974 -0.131151"/>
      <geometry>
        <mesh filename="file://$(find hubo_description)/hubo_gripper_meshes/Body_RF2_c1.STL"/>
      </geometry>
      <material name="">
        <color rgba="0.79216 0.81961 0.93333 1"/>
      </material>
    </visual>
    <collision>
      <origin rpy="-0.0022611089525 -0.7586841539 -1.53395243" xyz="-0.000564 0.015974 -0.131151"/>
      <geometry>
        <mesh filename="file://$(find hubo_description)/hubo_gripper_meshes/Body_RF2_c1_col.STL"/>
      </geometry>
    </collision>
    <inertial>
      <origin rpy="0 0 0" xyz="0 0 0"/>
      <mass value="0.038683"/>
      <inertia ixx="1.143e-04" ixy="7e-06" ixz="-6.53e-05" iyy="2.17e-04" iyz="-1e-05" izz="1.314e-04"/>
    </inertial>
  </link>
  <link name="Body_RF2_c2">
    <!--Finger 3 link 2-->
    <visual>
      <origin rpy="0 -1.47282576 -1.560806062" xyz="-0.001464 0.017671 -0.186731"/>
      <geometry>
        <mesh filename="file://$(find hubo_description)/hubo_gripper_meshes/Body_RF2_c2.STL"/>
      </geometry>
      <material name="">
        <color rgba="0.79216 0.81961 0.93333 1"/>
      </material>
    </visual>
    <collision>
      <origin rpy="0 -1.47282576 -1.560806062" xyz="-0.001464 0.017671 -0.186731"/>
      <geometry>
        <mesh filename="file://$(find hubo_description)/hubo_gripper_meshes/Body_RF2_c2_col.STL"/>
      </geometry>
    </collision>
    <inertial>
      <origin rpy="0 0 0" xyz="0 0 0"/>
      <mass value="0.05"/>
      <inertia ixx="2.31e-05" ixy="9e-06" ixz="-4.6e-06" iyy="7.09e-05" iyz="-5e-06" izz="6.69e-05"/>
    </inertial>
  </link>
  <link name="Body_RF2_c3">
    <!--Finger 3 link 3-->
    <visual>
      <origin rpy="0 -1.83156597 -1.50961381" xyz="-0.00071 0.022785 -0.22107"/>
      <geometry>
        <mesh filename="file://$(find hubo_description)/hubo_gripper_meshes/Body_RF2_c3.STL"/>
      </geometry>
      <material name="">
        <color rgba="0.79216 0.81961 0.93333 1"/>
      </material>
    </visual>
    <collision>
      <origin rpy="0 -1.83156597 -1.50961381" xyz="-0.00071 0.022785 -0.22107"/>
      <geometry>
        <mesh filename="file://$(find hubo_description)/hubo_gripper_meshes/Body_RF2_c3_col.STL"/>
      </geometry>
    </collision>
    <inertial>
      <origin rpy="0 0 0" xyz="0 0 0"/>
      <mass value="0.0115"/>
      <inertia ixx="7.2e-05" ixy="1e-06" ixz="2.9e-05" iyy="1.67e-05" iyz="1e-06" izz="1.84e-05"/>
    </inertial>
  </link>
  <joint name="RHAND_c1" type="revolute">
    <!--Joints connecting the links together and to the hand-->
    <parent link="Body_RF1"/>
    <child link="Body_RF2_c1"/>
    <axis xyz="-1 0 0"/>
    <limit effort="10000000" lower="0" upper="1" velocity="100"/>
  </joint>
  <joint name="RHAND_c2" type="revolute">
    <parent link="Body_RF2_c1"/>
    <child link="Body_RF2_c2"/>
    <axis xyz="-1 0 0"/>
    <limit effort="10000000" lower="0" upper="1" velocity="100"/>
  </joint>
  <joint name="RHAND_c3" type="revolute">
    <parent link="Body_RF2_c2"/>
    <child link="Body_RF2_c3"/>
    <axis xyz="-1 0 0"/>
    <limit effort="10000000" lower="0" upper="1" velocity="100"/>
  </joint>
  <link name="Body_RF1">
    <!-- Palm / Hand -->
    <visual>
      <origin rpy="0 0 -1.529072486" xyz="0 0 0"/>
      <geometry>
        <mesh filename="file://$(find hubo_description)/hubo_gripper_meshes/Body_RF1.STL"/>
      </geometry>
      <material name="">
        <color rgba="0.79216 0.81961 0.93333 1"/>
      </material>
    </visual>
    <collision>
      <origin rpy="0 0 -1.529072486" xyz="0 0 0"/>
      <geometry>
        <mesh filename="file://$(find hubo_description)/hubo_gripper_meshes/Body_RF1_col.STL"/>
      </geometry>
    </collision>
    <inertial>
      <origin rpy="0 0 0" xyz="0 0 0"/>
      <mass value="0.894667"/>
      <inertia ixx="0.00087045" ixy="-1.448e-05" ixz="-1.064e-05" iyy="0.00103972" iyz="-7.89e-06" izz="0.00095329"/>
    </inertial>
  </link>
  <link name="Body_LF2_a1">
    <!--Finger 1 link 1-->
    <visual>
      <origin rpy="0 0.740298856 -4.751623982" xyz="0.024026 0.019814 -0.130601"/>
      <geometry>
        <mesh filename="file://$(find hubo_description)/hubo_gripper_meshes/Body_LF2_a1.STL"/>
      </geometry>
      <material name="">
        <color rgba="0.79216 0.81961 0.93333 1"/>
      </material>
    </visual>
    <collision>
      <origin rpy="0 0.740298856 -4.751623982" xyz="0.024026 0.019814 -0.130601"/>
      <geometry>
        <mesh filename="file://$(find hubo_description)/hubo_gripper_meshes/Body_LF2_a1_col.STL"/>
      </geometry>
    </collision>
    <inertial>
      <origin rpy="0 0.740298856 -4.751623982" xyz="0.024625 0.033711 -0.156322"/>
      <mass value="0.038683"/>
      <inertia ixx="1.143e-04" ixy="7e-06" ixz="-6.53e-05" iyy="2.17e-04" iyz="-1e-05" izz="1.314e-04"/>
    </inertial>
  </link>
  <link name="Body_LF2_a2">
    <!--Finger 1 link 2-->
    <visual>
      <origin rpy="0 1.44624963 1.593054511" xyz="0.025431 0.021572 -0.187376"/>
      <geometry>
        <mesh filename="file://$(find hubo_description)/hubo_gripper_meshes/Body_LF2_a2.STL"/>
      </geometry>
      <material name="">
        <color rgba="0.79216 0.81961 0.93333 1"/>
      </material>
    </visual>
    <collision>
      <origin rpy="0 1.44624963 1.593054511" xyz="0.025431 0.021572 -0.187376"/>
      <geometry>
        <mesh filename="file://$(find hubo_description)/hubo_gripper_meshes/Body_LF2_a2_col.STL"/>
      </geometry>
    </collision>
    <inertial>
      <origin rpy="0 1.44624963 1.593054511" xyz="0.02523 0.03213 -0.201309"/>
      <mass value="0.021949"/>
      <inertia ixx="2.31e-05" ixy="9e-06" ixz="-4.6e-06" iyy="7.09e-05" iyz="-5e-06" izz="6.69e-05"/>
    </inertial>
  </link>
  <link name="Body_LF2_a3">
    <!--Finger 1 link 3-->
    <visual>
      <origin rpy="0 1.796537212 1.575056675" xyz="0.025389 0.026076 -0.222414"/>
      <geometry>
        <mesh filename="file://$(find hubo_description)/hubo_gripper_meshes/Body_LF2_a3.STL"/>
      </geometry>
      <material name="">
        <color rgba="0.79216 0.81961 0.93333 1"/>
      </material>
    </visual>
    <collision>
      <origin rpy="0 1.796537212 1.575056675" xyz="0.025389 0.026076 -0.222414"/>
      <geometry>
        <mesh filename="file://$(find hubo_description)/hubo_gripper_meshes/Body_LF2_a3_col.STL"/>
      </geometry>
    </collision>
    <inertial>
      <origin rpy="0 1.796537212 1.575056675" xyz="0.025366 0.031426 -0.235293"/>
      <mass value="0.0115"/>
      <inertia ixx="7.2e-05" ixy="1e-06" ixz="2.9e-05" iyy="1.67e-05" iyz="1e-06" izz="1.84e-05"/>
    </inertial>
  </link>
  <joint name="LHAND_a1" type="revolute">
    <!--Joints connecting the links together and to the hand-->
    <parent link="Body_LF1"/>
    <child link="Body_LF2_a1"/>
    <axis xyz="1 0 0"/>
    <limit effort="100" lower="0" upper="0.1149" velocity="100"/>
  </joint>
  <joint name="LHAND_a2" type="revolute">
    <parent link="Body_LF2_a1"/>
    <child link="Body_LF2_a2"/>
    <axis xyz="1 0 0"/>
    <limit effort="100" lower="0" upper="0.1149" velocity="100"/>
  </joint>
  <joint name="LHAND_a3" type="revolute">
    <parent link="Body_LF2_a2"/>
    <child link="Body_LF2_a3"/>
    <axis xyz="1 0 0"/>
    <limit effort="100" lower="0" upper="0.1149" velocity="100"/>
  </joint>
  <link name="Body_LF2_b1">
    <!--Finger 2 link 1-->
    <visual>
      <origin rpy="-0.02640700612 0.7209169742 1.640658366" xyz="-0.022975 0.016728 -0.132427"/>
      <geometry>
        <mesh filename="file://$(find hubo_description)/hubo_gripper_meshes/Body_LF2_b1.STL"/>
      </geometry>
      <material name="">
        <color rgba="0.79216 0.81961 0.93333 1"/>
      </material>
    </visual>
    <collision>
      <origin rpy="-0.02640700612 0.7209169742 1.640658366" xyz="-0.022975 0.016728 -0.132427"/>
      <geometry>
        <mesh filename="file://$(find hubo_description)/hubo_gripper_meshes/Body_LF2_b1_col.STL"/>
      </geometry>
    </collision>
    <inertial>
      <origin rpy="-0.02640700612 0.7209169742 1.640658366" xyz="-0.023675 0.031123 -0.15787"/>
      <mass value="0.038683"/>
      <inertia ixx="1.143e-04" ixy="7e-06" ixz="-6.53e-05" iyy="2.17e-04" iyz="-1e-05" izz="1.314e-04"/>
    </inertial>
  </link>
  <link name="Body_LF2_b2">
    <!--Finger 2 link 2-->
    <visual>
      <origin rpy="0 1.519176469 1.575374325" xyz="-0.023787 0.019722 -0.184149"/>
      <geometry>
        <mesh filename="file://$(find hubo_description)/hubo_gripper_meshes/Body_LF2_b2.STL"/>
      </geometry>
      <material name="">
        <color rgba="0.79216 0.81961 0.93333 1"/>
      </material>
    </visual>
    <collision>
      <origin rpy="0 1.519176469 1.575374325" xyz="-0.023787 0.019722 -0.184149"/>
      <geometry>
        <mesh filename="file://$(find hubo_description)/hubo_gripper_meshes/Body_LF2_b2_col.STL"/>
      </geometry>
    </collision>
    <inertial>
      <origin rpy="0 1.519176469 1.575374325" xyz="-0.023797 0.029239 -0.198814"/>
      <mass value="0.021949"/>
      <inertia ixx="2.31e-05" ixy="9e-06" ixz="-4.6e-06" iyy="7.09e-05" iyz="-5e-06" izz="6.69e-05"/>
    </inertial>
  </link>
  <link name="Body_LF2_b3">
    <!--Finger 2 link 3-->
    <visual>
      <origin rpy="-3.155066595 1.304865745 -1.517068111" xyz="-0.023113 0.022425 -0.21978"/>
      <geometry>
        <mesh filename="file://$(find hubo_description)/hubo_gripper_meshes/Body_LF2_b3.STL"/>
      </geometry>
      <material name="">
        <color rgba="0.79216 0.81961 0.93333 1"/>
      </material>
    </visual>
    <collision>
      <origin rpy="-3.155066595 1.304865745 -1.517068111" xyz="-0.023113 0.022425 -0.21978"/>
      <geometry>
        <mesh filename="file://$(find hubo_description)/hubo_gripper_meshes/Body_LF2_b3_col.STL"/>
      </geometry>
    </collision>
    <inertial>
      <origin rpy="-3.155066595 1.304865745 -1.517068111" xyz="-0.023481 0.02724 -0.232863"/>
      <mass value="0.0115"/>
      <inertia ixx="7.2e-05" ixy="1e-06" ixz="2.9e-05" iyy="1.67e-05" iyz="1e-06" izz="1.84e-05"/>
    </inertial>
  </link>
  <joint name="LHAND_b1" type="revolute">
    <!--Joints connecting the links together and to the hand-->
    <parent link="Body_LF1"/>
    <child link="Body_LF2_b1"/>
    <axis xyz="1 0 0"/>
    <limit effort="100" lower="0" upper="0.1149" velocity="100"/>
  </joint>
  <joint name="LHAND_b2" type="revolute">
    <parent link="Body_LF2_b1"/>
    <child link="Body_LF2_b2"/>
    <axis xyz="1 0 0"/>
    <limit effort="100" lower="0" upper="0.1149" velocity="100"/>
  </joint>
  <joint name="LHAND_b3" type="revolute">
    <parent link="Body_LF2_b2"/>
    <child link="Body_LF2_b3"/>
    <axis xyz="1 0 0"/>
    <limit effort="100" lower="0" upper="0.1149" velocity="100"/>
  </joint>
  <link name="Body_LF2_c1">
    <!--Finger 3 link 1-->
    <visual>
      <origin rpy="-0.0022611089525 -0.7586841539 1.565118771" xyz="0.000625 -0.0196 -0.131607"/>
      <geometry>
        <mesh filename="file://$(find hubo_description)/hubo_gripper_meshes/Body_LF2_c1.STL"/>
      </geometry>
      <material name="">
        <color rgba="0.79216 0.81961 0.93333 1"/>
      </material>
    </visual>
    <collision>
      <origin rpy="-0.0022611089525 -0.7586841539 1.565118771" xyz="0.000625 -0.0196 -0.131607"/>
      <geometry>
        <mesh filename="file://$(find hubo_description)/hubo_gripper_meshes/Body_LF2_c1_col.STL"/>
      </geometry>
    </collision>
    <inertial>
      <origin rpy="-0.0022611089525 -0.7586841539 1.565118771" xyz="0.000517 -0.033034 -0.157579"/>
      <mass value="0.038683"/>
      <inertia ixx="1.143e-04" ixy="7e-06" ixz="-6.53e-05" iyy="2.17e-04" iyz="-1e-05" izz="1.314e-04"/>
    </inertial>
  </link>
  <link name="Body_LF2_c2">
    <!--Finger 3 link 2-->
    <visual>
      <origin rpy="0 -1.47282576 1.538265135" xyz="0.00123 -0.019773 -0.188949"/>
      <geometry>
        <mesh filename="file://$(find hubo_description)/hubo_gripper_meshes/Body_LF2_c2.STL"/>
      </geometry>
      <material name="">
        <color rgba="0.79216 0.81961 0.93333 1"/>
      </material>
    </visual>
    <collision>
      <origin rpy="0 -1.47282576 1.538265135" xyz="0.00123 -0.019773 -0.188949"/>
      <geometry>
        <mesh filename="file://$(find hubo_description)/hubo_gripper_meshes/Body_LF2_c2_col.STL"/>
      </geometry>
    </collision>
    <inertial>
      <origin rpy="0 -1.47282576 1.538265135" xyz="0.000865 -0.029953 -0.203158"/>
      <mass value="0.05"/>
      <inertia ixx="2.31e-05" ixy="9e-06" ixz="-4.6e-06" iyy="7.09e-05" iyz="-5e-06" izz="6.69e-05"/>
    </inertial>
  </link>
  <link name="Body_LF2_c3">
    <!--Finger 3 link 3-->
    <visual>
      <origin rpy="0 -1.83156597 1.589457387" xyz="0.001096 -0.024086 -0.224421"/>
      <geometry>
        <mesh filename="file://$(find hubo_description)/hubo_gripper_meshes/Body_LF2_c3.STL"/>
      </geometry>
      <material name="">
        <color rgba="0.79216 0.81961 0.93333 1"/>
      </material>
    </visual>
    <collision>
      <origin rpy="0 -1.83156597 1.589457387" xyz="0.001096 -0.024086 -0.224421"/>
      <geometry>
        <mesh filename="file://$(find hubo_description)/hubo_gripper_meshes/Body_LF2_c3_col.STL"/>
      </geometry>
    </collision>
    <inertial>
      <origin rpy="0 -1.83156597 1.589457387" xyz="0.001188 -0.028981 -0.237479"/>
      <mass value="0.0115"/>
      <inertia ixx="7.2e-05" ixy="1e-06" ixz="2.9e-05" iyy="1.67e-05" iyz="1e-06" izz="1.84e-05"/>
    </inertial>
  </link>
  <joint name="LHAND_c1" type="revolute">
    <!--Joints connecting the links together and to the hand-->
    <parent link="Body_LF1"/>
    <child link="Body_LF2_c1"/>
    <axis xyz="-1 0 0"/>
    <limit effort="100" lower="0" upper="0.1149" velocity="100"/>
  </joint>
  <joint name="LHAND_c2" type="revolute">
    <parent link="Body_LF2_c1"/>
    <child link="Body_LF2_c2"/>
    <axis xyz="-1 0 0"/>
    <limit effort="100" lower="0" upper="0.1149" velocity="100"/>
  </joint>
  <joint name="LHAND_c3" type="revolute">
    <parent link="Body_LF2_c2"/>
    <child link="Body_LF2_c3"/>
    <axis xyz="-1 0 0"/>
    <limit effort="100" lower="0" upper="0.1149" velocity="100"/>
  </joint>
  <link name="Body_LF1">
    <!-- Palm / Hand -->
    <visual>
      <origin rpy="0 0 1.57" xyz="0 0 0"/>
      <geometry>
        <mesh filename="file://$(find hubo_description)/hubo_gripper_meshes/Body_LF1.STL"/>
      </geometry>
      <material name="">
        <color rgba="0.79216 0.81961 0.93333 1"/>
      </material>
    </visual>
    <collision>
      <origin rpy="0 0 1.57" xyz="0 0 0"/>
      <geometry>
        <mesh filename="file://$(find hubo_description)/hubo_gripper_meshes/Body_LF1_col.STL"/>
      </geometry>
    </collision>
    <inertial>
      <origin rpy="0 0 1.57" xyz="-0.000036 -0.000345 -0.105011"/>
      <mass value="0.894667"/>
      <inertia ixx="0.00087045" ixy="-1.448e-05" ixz="-1.064e-05" iyy="0.00103972" iyz="-7.89e-06" izz="0.00095329"/>
    </inertial>
  </link>
  <!--left wrist to left gripper-->
  <joint name="LWFT_gripper" type="fixed">
    <parent link="Body_LWP"/>
    <child link="Body_LF1"/>
  </joint>
  <!--right wrist to right gripper-->
  <joint name="RWFT_gripper" type="fixed">
    <parent link="Body_RWP"/>
    <child link="Body_RF1"/>
  </joint>
</robot>
