<?xml version="1.0" ?>
<robot name="hubo_right_gripper">
  <link name="Body_RF2_a1"> <!--Finger 1 link 1-->
    <visual>
      <origin xyz="-0.117639 -0.084794 -0.652938" rpy="0 0.740298856 -7.850700415" />
      <geometry>
        <mesh filename="package://hubo_description/hubo_gripper_meshes/Body_RF2_a1.STL" scale="5 5 5"/>
      </geometry>
    </visual>
    <collision>
      <origin xyz="-0.117639 -0.084794 -0.652938" rpy="0 0.740298856 -7.850700415" />
      <geometry>
        <mesh filename="package://hubo_description/hubo_gripper_meshes/Body_RF2_a1_col.STL" scale="5 5 5"/>
      </geometry>
    </collision>
    <inertial>
      <origin xyz="0 0 0" rpy="0 0 0" />
      <mass value="0.038683"/>
      <inertia ixx="1.143e-04" ixy="7e-06" ixz="-6.53e-05" iyy="2.17e-04" iyz="-1e-05" izz="1.314e-04"/>
    </inertial>
  </link>
  <link name="Body_RF2_a2"> <!--Finger 1 link 2-->
    <visual>
      <origin xyz="-0.123152 -0.095192 -0.935974" rpy="0 1.44624963 -1.506016686" />
      <geometry>
        <mesh filename="package://hubo_description/hubo_gripper_meshes/Body_RF2_a2.STL" scale="5 5 5"/>
      </geometry>
    </visual>
    <collision>
      <origin xyz="-0.123152 -0.095192 -0.935974" rpy="0 1.44624963 -1.506016686" />
      <geometry>
        <mesh filename="package://hubo_description/hubo_gripper_meshes/Body_RF2_a2_col.STL" scale="5 5 5"/>
      </geometry>
    </collision>
    <inertial>
      <origin xyz="0 0 0" rpy="0 0 0" />
      <mass value="0.021949"/>
      <inertia ixx="2.31e-05" ixy="9e-06" ixz="-4.6e-06" iyy="7.09e-05" iyz="-5e-06" izz="6.69e-05"/>
    </inertial>
  </link>
  <link name="Body_RF2_a3"> <!--Finger 1 link 3-->
    <visual>
      <origin xyz="-0.121566 -0.123195 -1.10888" rpy="0 1.796537212 -1.524014522" />
      <geometry>
        <mesh filename="package://hubo_description/hubo_gripper_meshes/Body_RF2_a3.STL" scale="5 5 5"/>
      </geometry>
    </visual>
    <collision>
      <origin xyz="-0.121566 -0.123195 -1.10888" rpy="0 1.796537212 -1.524014522" />
      <geometry>
        <mesh filename="package://hubo_description/hubo_gripper_meshes/Body_RF2_a3_col.STL" scale="5 5 5"/>
      </geometry>
    </collision>
    <inertial>
      <origin xyz="0 0 0" rpy="0 0 0" />
      <mass value="0.0115"/>
      <inertia ixx="7.2e-05" ixy="1e-06" ixz="2.9e-05" iyy="1.67e-05" iyz="1e-06" izz="1.84e-05"/>
    </inertial>
  </link>
  <joint name="RHAND_a1" type="revolute"> <!--Joints connecting the links together and to the hand-->
    <parent link="Body_RF1"/>
    <child link="Body_RF2_a1"/>
    <axis xyz="1 0 0"/> 
    <origin xyz="0 0 0" rpy="0 0 0" />
    <limit effort="100" lower="0" upper="0.1149" velocity="100"/> 
  </joint>
  <joint name="RHAND_a2" type="revolute"> 
    <parent link="Body_RF2_a1"/>
    <child link="Body_RF2_a2"/>
    <axis xyz="1 0 0"/> 
    <origin xyz="0 0 0" rpy="0 0 0" />
    <limit effort="100" lower="0" upper="0.1149" velocity="100"/> 
  </joint>
  <joint name="RHAND_a3" type="revolute">
    <parent link="Body_RF2_a2"/>
    <child link="Body_RF2_a3"/>
    <axis xyz="1 0 0"/>
    <origin xyz="0 0 0" rpy="0 0 0" />
    <limit effort="100" lower="0" upper="0.1149" velocity="100"/> 
  </joint>
  <link name="Body_RF2_b1"> <!--Finger 2 link 1-->
    <visual>
       <origin rpy="-0.02640700612 0.7209169742 -1.458412831" xyz="0.108724 -0.073082 -0.660735"/>
      <geometry>
        <mesh filename="package://hubo_description/hubo_gripper_meshes/Body_RF2_b1.STL" scale="5 5 5"/>
      </geometry>
    </visual>
    <collision>
       <origin rpy="-0.02640700612 0.7209169742 -1.458412831" xyz="0.108724 -0.073082 -0.660735"/>
      <geometry>
        <mesh filename="package://hubo_description/hubo_gripper_meshes/Body_RF2_b1_col.STL" scale="5 5 5"/>
      </geometry>
    </collision>
    <inertial>
     <origin xyz="0 0 0" rpy="0 0 0" />
      <mass value="0.038683"/>
      <inertia ixx="1.143e-04" ixy="7e-06" ixz="-6.53e-05" iyy="2.17e-04" iyz="-1e-05" izz="1.314e-04"/>
    </inertial>
  </link>
  <link name="Body_RF2_b2"> <!--Finger 2 link 2-->
    <visual>
      <origin rpy="0 1.519176469 -1.523696872" xyz="0.114394 -0.085859 -0.935232"/>
      <geometry>
        <mesh filename="package://hubo_description/hubo_gripper_meshes/Body_RF2_b2.STL" scale="5 5 5"/>
      </geometry>
    </visual>
    <collision>
      <origin rpy="0 1.519176469 -1.523696872" xyz="0.114394 -0.085859 -0.935232"/>
      <geometry>
        <mesh filename="package://hubo_description/hubo_gripper_meshes/Body_RF2_b2_col.STL" scale="5 5 5"/>
      </geometry>
    </collision>
    <inertial>
      <origin xyz="0 0 0" rpy="0 0 0" />
      <mass value="0.021949"/>
      <inertia ixx="2.31e-05" ixy="9e-06" ixz="-4.6e-06" iyy="7.09e-05" iyz="-5e-06" izz="6.69e-05"/>
    </inertial>
  </link>
  <link name="Body_RF2_b3"> <!--Finger 2 link 3-->
    <visual>
      <origin rpy="-3.155066595 1.304865745 -4.616134072" xyz="0.112984 -0.098744 -1.11514"/>
      <geometry>
        <mesh filename="package://hubo_description/hubo_gripper_meshes/Body_RF2_b3.STL" scale="5 5 5"/>
      </geometry>
    </visual>
    <collision>
       <origin rpy="-3.155066595 1.304865745 -4.616134072" xyz="0.112984 -0.098744 -1.11514"/>
      <geometry>
        <mesh filename="package://hubo_description/hubo_gripper_meshes/Body_RF2_b3_col.STL" scale="5 5 5"/>
      </geometry>
    </collision>
    <inertial>
      <origin xyz="0 0 0" rpy="0 0 0" />
      <mass value="0.0115"/>
      <inertia ixx="7.2e-05" ixy="1e-06" ixz="2.9e-05" iyy="1.67e-05" iyz="1e-06" izz="1.84e-05"/>
    </inertial>
  </link>
  <joint name="RHAND_b1" type="revolute"> <!--Joints connecting the links together and to the hand-->
    <parent link="Body_RF1"/>
    <child link="Body_RF2_b1"/>
    <axis xyz="1 0 0"/>
    <limit effort="100" lower="0" upper="0.1149" velocity="100"/> 
  </joint>
  <joint name="RHAND_b2" type="revolute">
    <parent link="Body_RF2_b1"/>
    <child link="Body_RF2_b2"/>
    <axis xyz="1 0 0"/>
    <limit effort="100" lower="0" upper="0.1149" velocity="100"/> 
  </joint>
  <joint name="RHAND_b3" type="revolute">
    <parent link="Body_RF2_b2"/>
    <child link="Body_RF2_b3"/>
    <axis xyz="1 0 0"/>
    <limit effort="100" lower="0" upper="0.1149" velocity="100"/> 
  </joint>
  <link name="Body_RF2_c1"> <!--Finger 3 link 1-->
    <visual>
      <origin rpy="-0.0022611089525 -0.7586841539 -1.53395243" xyz="0.004368 0.102227 -0.661851"/>
      <geometry>
        <mesh filename="package://hubo_description/hubo_gripper_meshes/Body_RF2_c1.STL" scale="5 5 5"/>
      </geometry>
    </visual>
    <collision>
      <origin rpy="-0.0022611089525 -0.7586841539 -1.53395243" xyz="0.004368 0.102227 -0.661851"/>
      <geometry>
        <mesh filename="package://hubo_description/hubo_gripper_meshes/Body_RF2_c1_col.STL" scale="5 5 5"/>
      </geometry>
    </collision>
    <inertial>
      <origin xyz="0 0 0" rpy="0 0 0" />
      <mass value="0.038683"/>
      <inertia ixx="1.143e-04" ixy="7e-06" ixz="-6.53e-05" iyy="2.17e-04" iyz="-1e-05" izz="1.314e-04"/>
    </inertial>
  </link>
  <link name="Body_RF2_c2"> <!--Finger 3 link 2-->
    <visual>
      <origin rpy="0 -1.47282576 -1.560806062" xyz="0.000799 0.10894 -0.945134"/>
      <geometry>
        <mesh filename="package://hubo_description/hubo_gripper_meshes/Body_RF2_c2.STL" scale="5 5 5"/>
      </geometry>
    </visual>
    <collision>
     <origin rpy="0 -1.47282576 -1.560806062" xyz="0.000799 0.10894 -0.945134"/>
      <geometry>
        <mesh filename="package://hubo_description/hubo_gripper_meshes/Body_RF2_c2_col.STL" scale="5 5 5"/>
      </geometry>
    </collision>
    <inertial>
      <origin xyz="0 0 0" rpy="0 0 0" />
      <mass value="0.05"/>
      <inertia ixx="2.31e-05" ixy="9e-06" ixz="-4.6e-06" iyy="7.09e-05" iyz="-5e-06" izz="6.69e-05"/>
    </inertial>
  </link>
  <link name="Body_RF2_c3"> <!--Finger 3 link 3-->
    <visual>
      <origin rpy="0 -1.83156597 -1.50961381" xyz="0.003696 0.137904 -1.11899"/>
      <geometry>
        <mesh filename="package://hubo_description/hubo_gripper_meshes/Body_RF2_c3.STL" scale="5 5 5"/>
      </geometry>
    </visual>
    <collision>
      <origin rpy="0 -1.83156597 -1.50961381" xyz="0.003696 0.137904 -1.11899"/>
      <geometry>
        <mesh filename="package://hubo_description/hubo_gripper_meshes/Body_RF2_c3_col.STL" scale="5 5 5"/>
      </geometry>
    </collision>
    <inertial>
      <origin rpy="0 0 0" xyz="0 0 0"/>
      <mass value="0.0115"/>
      <inertia ixx="7.2e-05" ixy="1e-06" ixz="2.9e-05" iyy="1.67e-05" iyz="1e-06" izz="1.84e-05"/>
    </inertial>
  </link>
  <joint name="RHAND_c1" type="revolute"> <!--Joints connecting the links together and to the hand-->
    <parent link="Body_RF1"/>
    <child link="Body_RF2_c1"/>
    <axis xyz="-1 0 0"/>
    <origin xyz="0 0 0" rpy="0 0 0" />
    <limit effort="100" lower="0" upper="0.1149" velocity="100"/> 
  </joint>
  <joint name="RHAND_c2" type="revolute">
    <parent link="Body_RF2_c1"/>
    <child link="Body_RF2_c2"/>
    <axis xyz="-1 0 0"/>
    <origin xyz="0 0 0" rpy="0 0 0" />
    <limit effort="100" lower="0" upper="0.1149" velocity="100"/> 
  </joint>
  <joint name="RHAND_c3" type="revolute">
    <parent link="Body_RF2_c2"/>
    <child link="Body_RF2_c3"/>
    <axis xyz="-1 0 0"/>
    <origin xyz="0 0 0" rpy="0 0 0" />
    <limit effort="100" lower="0" upper="0.1149" velocity="100" /> 
  </joint>
  <link name="Body_RF1"> <!-- Palm / Hand -->
    <visual>
      <origin xyz="0 0 0" rpy="0 0 -1.529072486" />
      <geometry>
        <mesh filename="package://hubo_description/hubo_gripper_meshes/Body_RF1.STL" scale="5 5 5"/>
      </geometry>
    </visual>
    <collision>
      <origin xyz="0 0 0" rpy="0 0 -1.529072486" />
      <geometry>
        <mesh filename="package://hubo_description/hubo_gripper_meshes/Body_RF1_col.STL" scale="5 5 5"/>
      </geometry>
    </collision>
    <inertial>
      <origin rpy="0 0 0" xyz="0 0 0"/>
      <mass value="0.894667"/>
      <inertia ixx="0.00087045" ixy="-1.448e-05" ixz="-1.064e-05" iyy="0.00103972" iyz="-7.89e-06" izz="0.00095329"/>
    </inertial>
  </link>
</robot>
