<?xml version="1.0" ?>
<robot name="hubo_left_gripper">
  <link name="Body_LF2_a1"> <!--Finger 1 link 1-->
    <visual>
      <origin xyz="0.110467 0.093131 -0.652938" rpy="0 0.740298856 -4.751623982" />
      <geometry>
        <mesh filename="package://hubo_description/hubo_gripper_meshes/Body_LF2_a1.STL" scale="5 5 5"/>
      </geometry>
    </visual>
    <collision>
      <origin xyz="0.110467 0.093131 -0.652938" rpy="0 0.740298856 -4.751623982" />
      <geometry>
        <mesh filename="package://hubo_description/hubo_gripper_meshes/Body_LF2_a1_col.STL" scale="5 5 5"/>
      </geometry>
    </collision>
    <inertial>
      <origin xyz="0 0 0" rpy="0 0 0" />
      <mass value="0.038683"/>
      <inertia ixx="1.143e-04" ixy="7e-06" ixz="-6.53e-05" iyy="2.17e-04" iyz="-1e-05" izz="1.314e-04"/>
    </inertial>
  </link>
  <link name="Body_LF2_a2"> <!--Finger 1 link 2-->
    <visual>
      <origin xyz="0.116417 0.103285 -0.935974" rpy="0 1.44624963 1.593054511" />
      <geometry>
        <mesh filename="package://hubo_description/hubo_gripper_meshes/Body_LF2_a2.STL" scale="5 5 5"/>
      </geometry>
    </visual>
    <collision>
      <origin xyz="0.116417 0.103285 -0.935974" rpy="0 1.44624963 1.593054511" />
      <geometry>
        <mesh filename="package://hubo_description/hubo_gripper_meshes/Body_LF2_a2_col.STL" scale="5 5 5"/>
      </geometry>
    </collision>
    <inertial>
      <origin xyz="0 0 0" rpy="0 0 0" />
      <mass value="0.021949"/>
      <inertia ixx="2.31e-05" ixy="9e-06" ixz="-4.6e-06" iyy="7.09e-05" iyz="-5e-06" izz="6.69e-05"/>
    </inertial>
  </link>
  <link name="Body_LF2_a3"> <!--Finger 1 link 3-->
    <visual>
      <origin xyz="0.116023 0.13133 -1.10888" rpy="0 1.796537212 1.575056675" />
      <geometry>
        <mesh filename="package://hubo_description/hubo_gripper_meshes/Body_LF2_a3.STL" scale="5 5 5"/>
      </geometry>
    </visual>
    <collision>
      <origin xyz="0.116023 0.13133 -1.10888" rpy="0 1.796537212 1.575056675" />
      <geometry>
        <mesh filename="package://hubo_description/hubo_gripper_meshes/Body_LF2_a3_col.STL" scale="5 5 5"/>
      </geometry>
    </collision>
    <inertial>
      <origin xyz="0 0 0" rpy="0 0 0" />
      <mass value="0.0115"/>
      <inertia ixx="7.2e-05" ixy="1e-06" ixz="2.9e-05" iyy="1.67e-05" iyz="1e-06" izz="1.84e-05"/>
    </inertial>
  </link>
  <joint name="LHAND_a1" type="revolute"> <!--Joints connecting the links together and to the hand-->
    <parent link="Body_LF1"/>
    <child link="Body_LF2_a1"/>
    <axis xyz="1 0 0"/> 
    <limit effort="100" lower="0" upper="0.1149" velocity="100"/> 
  </joint>
  <joint name="LHAND_a2" type="revolute"> 
    <parent link="Body_LF2_a1"/>
    <child link="Body_LF2_a2"/>
    <axis xyz="-1 0 0"/>
    <limit effort="100" lower="0" upper="0.1149" velocity="100"/> 
  </joint>
  <joint name="LHAND_a3" type="revolute">
    <parent link="Body_LF2_a2"/>
    <child link="Body_LF2_a3"/>
    <axis xyz="-1 0 0"/>
    <limit effort="100" lower="0" upper="0.1149" velocity="100"/> 
  </joint>
  <link name="Body_LF2_b1"> <!--Finger 2 link 1-->
    <visual>
       <origin rpy="-0.02640700612 0.7209169742 1.640658366" xyz="-0.114135 0.094376 -0.660685"/>
      <geometry>
        <mesh filename="package://hubo_description/hubo_gripper_meshes/Body_LF2_b1.STL" scale="5 5 5"/>
      </geometry>
    </visual>
    <collision>
       <origin rpy="-0.02640700612 0.7209169742 1.640658366" xyz="-0.114135 0.094376 -0.660685"/>
      <geometry>
        <mesh filename="package://hubo_description/hubo_gripper_meshes/Body_LF2_b1_col.STL" scale="5 5 5"/>
      </geometry>
    </collision>
    <inertial>
     <origin xyz="0 0 0" rpy="0 0 0" />
      <mass value="0.038683"/>
      <inertia ixx="1.143e-04" ixy="7e-06" ixz="-6.53e-05" iyy="2.17e-04" iyz="-1e-05" izz="1.314e-04"/>
    </inertial>
  </link>
  <link name="Body_LF2_b2"> <!--Finger 2 link 2-->
    <visual>
      <origin rpy="0 1.519176469 1.575374325" xyz="-0.119256 0.107382 -0.935182"/>
      <geometry>
        <mesh filename="package://hubo_description/hubo_gripper_meshes/Body_LF2_b2.STL" scale="5 5 5"/>
      </geometry>
    </visual>
    <collision>
      <origin rpy="0 1.519176469 1.575374325" xyz="-0.119256 0.107382 -0.935182"/>
      <geometry>
        <mesh filename="package://hubo_description/hubo_gripper_meshes/Body_LF2_b2_col.STL" scale="5 5 5"/>
      </geometry>
    </collision>
    <inertial>
      <origin xyz="0 0 0" rpy="0 0 0" />
      <mass value="0.021949"/>
      <inertia ixx="2.31e-05" ixy="9e-06" ixz="-4.6e-06" iyy="7.09e-05" iyz="-5e-06" izz="6.69e-05"/>
    </inertial>
  </link>
  <link name="Body_LF2_b3"> <!--Finger 2 link 3-->
    <visual>
      <origin rpy="-3.155066595 1.304865745 -1.517068111" xyz="-0.1173 0.120196 -1.11509"/>
      <geometry>
        <mesh filename="package://hubo_description/hubo_gripper_meshes/Body_LF2_b3.STL" scale="5 5 5"/>
      </geometry>
    </visual>
    <collision>
       <origin rpy="-3.155066595 1.304865745 -1.517068111" xyz="-0.1173 0.120196 -1.11509"/>
      <geometry>
        <mesh filename="package://hubo_description/hubo_gripper_meshes/Body_LF2_b3_col.STL" scale="5 5 5"/>
      </geometry>
    </collision>
    <inertial>
      <origin xyz="0 0 0" rpy="0 0 0" />
      <mass value="0.0115"/>
      <inertia ixx="7.2e-05" ixy="1e-06" ixz="2.9e-05" iyy="1.67e-05" iyz="1e-06" izz="1.84e-05"/>
    </inertial>
  </link>
  <joint name="LHAND_b1" type="revolute"> <!--Joints connecting the links together and to the hand-->
    <parent link="Body_LF1"/>
    <child link="Body_LF2_b1"/>
    <axis xyz="1 0 0"/>
    <limit effort="100" lower="0" upper="0.1149" velocity="100"/> 
  </joint>
  <joint name="LHAND_b2" type="revolute">
    <parent link="Body_LF2_b1"/>
    <child link="Body_LF2_b2"/>
    <axis xyz="1 0 0"/>
    <limit effort="100" lower="0" upper="0.1149" velocity="100"/> 
  </joint>
  <joint name="LHAND_b3" type="revolute">
    <parent link="Body_LF2_b2"/>
    <child link="Body_LF2_b3"/>
    <axis xyz="1 0 0"/>
    <limit effort="100" lower="0" upper="0.1149" velocity="100"/> 
  </joint>
  <link name="Body_LF2_c1"> <!--Finger 3 link 1-->
    <visual>
      <origin rpy="-0.0022611089525 -0.7586841539 1.565118771" xyz="0.000709 -0.101893 -0.650424"/>
      <geometry>
        <mesh filename="package://hubo_description/hubo_gripper_meshes/Body_LF2_c1.STL" scale="5 5 5"/>
      </geometry>
    </visual>
    <collision>
      <origin rpy="-0.0022611089525 -0.7586841539 1.565118771" xyz="0.000709 -0.101893 -0.650424"/>
      <geometry>
        <mesh filename="package://hubo_description/hubo_gripper_meshes/Body_LF2_c1_col.STL" scale="5 5 5"/>
      </geometry>
    </collision>
    <inertial>
      <origin xyz="0 0 0" rpy="0 0 0" />
      <mass value="0.038683"/>
      <inertia ixx="1.143e-04" ixy="7e-06" ixz="-6.53e-05" iyy="2.17e-04" iyz="-1e-05" izz="1.314e-04"/>
    </inertial>
  </link>
  <link name="Body_LF2_c2"> <!--Finger 3 link 2-->
    <visual>
      <origin rpy="0 -1.47282576 1.538265135" xyz="0.00399 -0.108752 -0.933707"/>
      <geometry>
        <mesh filename="package://hubo_description/hubo_gripper_meshes/Body_LF2_c2.STL" scale="5 5 5"/>
      </geometry>
    </visual>
    <collision>
     <origin rpy="0 -1.47282576 1.538265135" xyz="0.00399 -0.108752 -0.933707"/>
      <geometry>
        <mesh filename="package://hubo_description/hubo_gripper_meshes/Body_LF2_c2_col.STL" scale="5 5 5"/>
      </geometry>
    </collision>
    <inertial>
      <origin xyz="0 0 0" rpy="0 0 0" />
      <mass value="0.05"/>
      <inertia ixx="2.31e-05" ixy="9e-06" ixz="-4.6e-06" iyy="7.09e-05" iyz="-5e-06" izz="6.69e-05"/>
    </inertial>
  </link>
  <link name="Body_LF2_c3"> <!--Finger 3 link 3-->
    <visual>
      <origin rpy="0 -1.83156597 1.589457387" xyz="-0.000136 -0.137567 -1.10756"/>
      <geometry>
        <mesh filename="package://hubo_description/hubo_gripper_meshes/Body_LF2_c3.STL" scale="5 5 5"/>
      </geometry>
    </visual>
    <collision>
      <origin rpy="0 -1.83156597 1.589457387" xyz="-0.000136 -0.137567 -1.10756"/>
      <geometry>
        <mesh filename="package://hubo_description/hubo_gripper_meshes/Body_LF2_c3_col.STL" scale="5 5 5"/>
      </geometry>
    </collision>
    <inertial>
      <origin xyz="0 0 0" rpy="0 0 0" />
      <mass value="0.0115"/>
      <inertia ixx="7.2e-05" ixy="1e-06" ixz="2.9e-05" iyy="1.67e-05" iyz="1e-06" izz="1.84e-05"/>
    </inertial>
  </link>
  <joint name="LHAND_c1" type="revolute"> <!--Joints connecting the links together and to the hand-->
    <parent link="Body_LF1"/>
    <child link="Body_LF2_c1"/>
    <axis xyz="1 0 0"/>
    <limit effort="100" lower="0" upper="0.1149" velocity="100"/> 
  </joint>
  <joint name="LHAND_c2" type="revolute">
    <parent link="Body_LF2_c1"/>
    <child link="Body_LF2_c2"/>
    <axis xyz="1 0 0"/>
    <limit effort="100" lower="0" upper="0.1149" velocity="100"/> 
  </joint>
  <joint name="LHAND_c3" type="revolute">
    <parent link="Body_LF2_c2"/>
    <child link="Body_LF2_c3"/>
    <axis xyz="1 0 0"/>
    <limit effort="100" lower="0" upper="0.1149" velocity="100" /> 
  </joint>
  <link name="Body_LF1"> <!-- Palm / Hand -->
    <visual>
      <origin xyz="0 0 0" rpy="0 0 1.57" />
      <geometry>
        <mesh filename="package://hubo_description/hubo_gripper_meshes/Body_LF1.STL" scale="5 5 5"/>
      </geometry>
    </visual>
    <collision>
      <origin xyz="0 0 0" rpy="0 0 1.57" />
      <geometry>
        <mesh filename="package://hubo_description/hubo_gripper_meshes/Body_LF1_col.STL" scale="5 5 5"/>
      </geometry>
    </collision>
    <inertial>
      <origin rpy="0 0 0" xyz="0 0 0"/>
      <mass value="0.894667"/>
      <inertia ixx="0.00087045" ixy="-1.448e-05" ixz="-1.064e-05" iyy="0.00103972" iyz="-7.89e-06" izz="0.00095329"/>
    </inertial>
  </link>
</robot>
